<mujoco model="rb5_850e">
  <compiler angle="radian"/>
  <asset>
    <material class="rb5_850e" name="black" rgba="0.033 0.033 0.033 1" />
    <material class="rb5_850e" name="jointgray" rgba="0.278 0.278 0.278 1" />
    <material class="rb5_850e" name="linkgray" rgba="0.82 0.82 0.82 1" />
    <material class="rb5_850e" name="urblue" rgba="0.49 0.678 0.8 1" />
    <mesh name="link0" file="link0.stl"/>
    <mesh name="link1" file="link1.stl"/>
    <mesh name="link2" file="link2.stl"/>
    <mesh name="link3" file="link3.stl"/>
    <mesh name="link4" file="link4.stl"/>
    <mesh name="link5" file="link5.stl"/>
    <mesh name="link6" file="link6.stl"/>
  </asset>
  <asset>
    <material name="XID_Default_28FDDE125FCD40CB85B4287EFC819E04_shader" specular="0.5" shininess="0.5" rgba="0.8 0.8 0.8 1"/>
    <material name="XID_768588_2E571D5978994D3ABAE2BF078BC8457F_shader" specular="0.5" shininess="0.5" rgba="0.0722719 0.0908417 0.0975874 1"/>
    <material name="255,255,255" specular="0.5" shininess="0.5" rgba="0.8 0.8 0.8 1"/>
    <material name="0,153,255" specular="0.5" shininess="0.5" rgba="0.8 0.8 0.8 1"/>
    <mesh file="link0_0.obj"/>
    <mesh file="link0_1.obj"/>
    <mesh file="link0_2.obj"/>
    <mesh file="link0_3.obj"/>
  </asset>
  <asset>
    <material name="0,153,255_1" specular="0.5" shininess="0.5" rgba="0.8 0.8 0.8 1"/>
    <material name="76,85,88" specular="0.5" shininess="0.5" rgba="0.3 0.3 0.3 1"/>
    <material name="64,64,64" specular="0.5" shininess="0.5" rgba="0.1 0.1 0.1 1"/>
    <material name="Material.004" specular="0.5" shininess="0.5" rgba="0.8 0.8 0.8 1"/>
    <mesh file="link1_0.obj"/>
    <mesh file="link1_1.obj"/>
    <mesh file="link1_2.obj"/>
    <mesh file="link1_3.obj"/>
  </asset>
  <asset>
    <material name="64,64,64_1" specular="0.5" shininess="0.5" rgba="0.1 0.1 0.1 1"/>
    <material name="128,128,128_1" specular="0.5" shininess="0.5" rgba="0.1 0.1 0.1 1"/>
    <material name="255,255,255_2" specular="0.5" shininess="0.5" rgba="0.8 0.8 0.8 1"/>
    <material name="76,85,88_1" specular="0.5" shininess="0.5" rgba="0.3 0.3 0.3 1"/>
    <material name="0,153,255_2" specular="0.5" shininess="0.5" rgba="0.8 0.8 0.8 1"/>
    <material name="153,153,153" specular="0.5" shininess="0.5" rgba="0.3 0.3 0.3 1"/>
    <material name="Material.005" specular="0.5" shininess="0.5" rgba="0.8 0.8 0.8 1"/>
    <material name="Material.006" specular="0.5" shininess="0.5" rgba="0.8 0.8 0.8 1"/>
    <material name="Material.008" specular="0.5" shininess="0.5" rgba="0 0.05000019 0.1 1"/>
    <mesh file="link2_0.obj"/>
    <mesh file="link2_1.obj"/>
    <mesh file="link2_2.obj"/>
    <mesh file="link2_3.obj"/>
    <mesh file="link2_4.obj"/>
    <mesh file="link2_5.obj"/>
    <mesh file="link2_6.obj"/>
    <mesh file="link2_7.obj"/>
    <mesh file="link2_8.obj"/>
  </asset>
  <asset>
    <material name="153,153,153_1" specular="0.5" shininess="0.5" rgba="0.3 0.3 0.3 1"/>
    <material name="64,64,64_2" specular="0.5" shininess="0.5" rgba="0.1 0.1 0.1 1"/>
    <material name="204,204,204" specular="0.5" shininess="0.5" rgba="0.1 0.1 0.1 1"/>
    <material name="244,244,244" specular="0.5" shininess="0.5" rgba="0.8 0.8 0.8 1"/>
    <material name="125,125,125" specular="0.5" shininess="0.5" rgba="0.3 0.3 0.3 1"/>
    <material name="0,153,255_3" specular="0.5" shininess="0.5" rgba="0.8 0.8 0.8 1"/>
    <material name="128,162,180" specular="0.5" shininess="0.5" rgba="0.3 0.3 0.3 1"/>
    <material name="Material.002" specular="0.5" shininess="0.5" rgba="0.8 0.8 0.8 1"/>
    <material name="Material.003" specular="0.5" shininess="0.5" rgba="0.8 0.8 0.8 1"/>
    <mesh file="link3_0.obj"/>
    <mesh file="link3_1.obj"/>
    <mesh file="link3_2.obj"/>
    <mesh file="link3_3.obj"/>
    <mesh file="link3_4.obj"/>
    <mesh file="link3_5.obj"/>
    <mesh file="link3_6.obj"/>
    <mesh file="link3_7.obj"/>
    <mesh file="link3_8.obj"/>
  </asset>
  <asset>
    <material name="244,244,244_1" specular="0.5" shininess="0.5" rgba="0.8 0.8 0.8 1"/>
    <material name="125,125,125_1" specular="0.5" shininess="0.5" rgba="0.3 0.3 0.3 1"/>
    <material name="204,204,204_1" specular="0.5" shininess="0.5" rgba="0.1 0.1 0.1 1"/>
    <material name="64,64,64_3" specular="0.5" shininess="0.5" rgba="0.1 0.1 0.1 1"/>
    <material name="Material.007" specular="0.5" shininess="0.5" rgba="0.8 0.8 0.8 1"/>
    <mesh file="link4_0.obj"/>
    <mesh file="link4_1.obj"/>
    <mesh file="link4_2.obj"/>
    <mesh file="link4_3.obj"/>
    <mesh file="link4_4.obj"/>
  </asset>
  <asset>
    <material name="244,244,244_2" specular="0.5" shininess="0.5" rgba="0.8 0.8 0.8 1"/>
    <material name="125,125,125_2" specular="0.5" shininess="0.5" rgba="0.3 0.3 0.3 1"/>
    <material name="204,204,204_2" specular="0.5" shininess="0.5" rgba="0.1 0.1 0.1 1"/>
    <material name="64,64,64_4" specular="0.5" shininess="0.5" rgba="0.1 0.1 0.1 1"/>
    <material name="Material.001" specular="0.5" shininess="0.5" rgba="0.8 0.8 0.8 1"/>
    <mesh file="link5_0.obj"/>
    <mesh file="link5_1.obj"/>
    <mesh file="link5_2.obj"/>
    <mesh file="link5_3.obj"/>
    <mesh file="link5_4.obj"/>
  </asset>
  <asset>
    <material name="128,128,128_3" specular="0.5" shininess="0.5" rgba="0.3 0.3 0.3 1"/>
    <material name="254,254,255" specular="0.5" shininess="0.5" rgba="0.8 0.8 0.8 1"/>
    <mesh file="link6_0.obj"/>
    <mesh file="link6_1.obj"/>
  </asset>

  <default>
    <default class="rb5_850e">
      <material specular="0.5" shininess="0.25" />
      <joint axis="0 1 0" range="-6.28319 6.28319" armature="0.1" />
      <general gaintype="fixed" biastype="affine" ctrlrange="-6.2831 6.2831" gainprm="400"
        biasprm="0 -400 -120" forcerange="-80 80" />
      <default class="size3">
        <default class="size3_limited">
          <joint range="-3.1415 3.1415" />
          <general ctrlrange="-3.1415 3.1415" />
        </default>
      </default>
      <default class="size1">
        <general gainprm="40" biasprm="0 -40 -30" forcerange="-28 28" />
      </default>
      <default class="visual">
        <geom type="mesh" contype="0" conaffinity="0" group="2" />
      </default>
      <default class="collision">
        <geom type="capsule" group="3" />
        <default class="eef_collision">
          <geom type="cylinder" />
        </default>
      </default>
      <site size="0.001" rgba="0.5 0.5 0.5 0.3" group="4" />
    </default>
  </default>

  <worldbody>
    <body name="link0" pos="0 0 0">
    <geom type="mesh" mesh="link0" class="visual"/>
    <geom mesh="link0_0" material="0,153,255" class="visual"/>
    <geom mesh="link0_1" material="255,255,255" class="visual"/>
    <geom mesh="link0_2" material="XID_768588_2E571D5978994D3ABAE2BF078BC8457F_shader" class="visual"/>
    <geom mesh="link0_3" material="XID_Default_28FDDE125FCD40CB85B4287EFC819E04_shader" class="visual"/>
    <geom mesh="link0_0" class="collision"/>
    <!-- <geom mesh="link0_1" class="collision"/>
    <geom mesh="link0_2" class="collision"/>
    <geom mesh="link0_3" class="collision"/> -->
      <body name="link1" pos="0 0 0.1692">
        <inertial pos="5.7e-05 -0.005795 -0.034516" quat="0.676677 0.181125 -0.183239 0.689729" mass="4.147" diaginertia="0.00940157 0.00878691 0.0073332"/>
        <joint name="base" pos="0 0 0" axis="0 0 1" range="-3.14 3.14" actuatorfrcrange="-150 150" />
        <geom mesh="link1_0" material="Material.004" class="visual"/>
        <geom mesh="link1_1" material="64,64,64" class="visual"/>
        <geom mesh="link1_2" material="76,85,88" class="visual"/>
        <geom mesh="link1_3" material="0,153,255_1" class="visual"/>
        <geom class="collision" size="0.06 0.02" rgba="0 1 0 0.3" pos="0 0 0"/>
        <geom class="collision" size="0.06 0.04" rgba="0 1 0 0.3" pos="0 -0.08 0.01" euler="1.57018 0 0"/>
        <!-- <geom mesh="link1_0" class="collision"/> -->
        <!-- <geom mesh="link1_1" class="collision"/> -->
        <!-- <geom mesh="link1_2" class="collision"/> -->
        <!-- <geom mesh="link1_3" class="collision"/> -->
        <!-- <site name="link1_iner" pos="5.7e-05 -0.005795 -0.034516" rgba="0 1 0 0.5"/> -->
        <body name="link2">
          <inertial pos="-3.7e-05 -0.121603 0.212933" quat="0.999997 0.000348233 7.80187e-05 -0.00223104" mass="9.633" diaginertia="0.392214 0.388915 0.0219492"/>
          <!-- <site name="link2_iner" pos="-3.7e-05 -0.121603 0.212933" rgba="0 1 0 0.5"/> -->
          <joint name="shoulder" pos="0 0 0" axis="0 1 0" range="-3.14 3.14" actuatorfrcrange="-150 150" />
          <geom mesh="link2_0" material="Material.008" class="visual"/>
          <geom mesh="link2_1" material="Material.006" class="visual"/>
          <geom mesh="link2_2" material="Material.005" class="visual"/>
          <geom mesh="link2_3" material="153,153,153" class="visual"/>
          <geom mesh="link2_4" material="0,153,255_2" class="visual"/>
          <geom mesh="link2_5" material="76,85,88_1" class="visual"/>
          <geom mesh="link2_6" material="255,255,255_2" class="visual"/>
          <geom mesh="link2_7" material="128,128,128_1" class="visual"/>
          <geom mesh="link2_8" material="64,64,64_1" class="visual"/>
          <!-- <geom mesh="link2_0" class="collision"/> -->
          <!-- <geom mesh="link2_1" class="collision"/> -->
          <!-- <geom mesh="link2_2" class="collision"/> -->
          <!-- <geom mesh="link2_3" class="collision"/> -->
          <!-- <geom mesh="link2_4" class="collision"/> -->
          <!-- <geom mesh="link2_5" class="collision"/> -->
          <!-- <geom mesh="link2_6" class="collision"/> -->
          <!-- <geom mesh="link2_7" class="collision"/> -->
          <geom mesh="link2_8" class="collision" rgba="0 1 0 0.3" />
          <body name="link3" pos="0 0 0.425">
            <inertial pos="2.1e-05 -0.015845 0.202568" quat="0.999948 0.0100341 -5.40187e-05 -0.00170427" mass="3.915" diaginertia="0.11204 0.111832 0.0075271"/>
            <!-- <site name="link3_iner" pos="2.1e-05 -0.015845 0.202568" rgba="0 1 0 0.5"/> -->
            <joint name="elbow" class="size3_limited" pos="0 0 0" axis="0 1 0" range="-3.14 3.14" actuatorfrcrange="-150 150" />
            <geom mesh="link3_0" material="Material.003" class="visual"/>
            <geom mesh="link3_1" material="Material.002" class="visual"/>
            <geom mesh="link3_2" material="128,162,180" class="visual"/>
            <geom mesh="link3_3" material="0,153,255_3" class="visual"/>
            <geom mesh="link3_4" material="125,125,125" class="visual"/>
            <geom mesh="link3_5" material="244,244,244" class="visual"/>
            <geom mesh="link3_6" material="204,204,204" class="visual"/>
            <geom mesh="link3_7" material="64,64,64_2" class="visual"/>
            <geom mesh="link3_8" material="153,153,153_1" class="visual"/>
            <!-- <geom mesh="link3_0" class="collision"/> -->
            <!-- <geom mesh="link3_1" class="collision"/> -->
            <!-- <geom mesh="link3_2" class="collision"/> -->
            <geom class="collision" size="0.05 0.055" rgba="0 1 0 0.3" pos="0 -0.06 0.010" euler="1.57018 0 0"/>
            <!-- <geom mesh="link3_3" class="collision" euler="0 0 1.57"/> -->
            <!-- <geom mesh="link3_4" class="collision"/> -->
            <!-- <geom mesh="link3_5" class="collision"/> -->
            <!-- <geom mesh="link3_6" class="collision"/> -->
            <!-- <geom mesh="link3_7" class="collision"/> -->
            <!-- <geom mesh="link3_8" class="collision"/> -->
            <geom class="collision" size="0.04 0.2" rgba="0 1 0 0.3" pos="0 0 0.2"/>
            <body name="link4" pos="0 0 0.392">
              <inertial pos="5.7e-05 -0.106332 0.025881" quat="0.986693 0.162394 -0.00142514 0.00799378" mass="1.452" diaginertia="0.00162904 0.00160108 0.00118182"/>
              <!-- <site name="link4_iner" pos="5.7e-05 -0.106332 0.025881" rgba="0 1 0 0.5"/> -->
              <joint name="wrist1" pos="0 0 0" axis="0 1 0" range="-3.14 3.14" actuatorfrcrange="-10 10" />
              <geom mesh="link4_0" material="Material.007" class="visual"/>
              <geom mesh="link4_1" material="64,64,64_3" class="visual"/>
              <geom mesh="link4_2" material="204,204,204_1" class="visual"/>
              <geom mesh="link4_3" material="125,125,125_1" class="visual"/>
              <geom mesh="link4_4" material="244,244,244_1" class="visual"/>
              <geom class="collision" size="0.04 0.045" rgba="0 1 0 0.3" pos="0 -0.05 0.007" euler="1.57 0 0"/>
              <!-- <geom mesh="link4_0" class="collision"/>
              <geom mesh="link4_1" class="collision"/>
              <geom mesh="link4_2" class="collision"/>
              <geom mesh="link4_3" class="collision"/>
              <geom mesh="link4_4" class="collision"/> -->
              <body name="link5" pos="0 -0.1107 0.1107">
                <inertial pos="-2.8e-05 -0.025911 -0.004363" quat="0.812497 0.582798 -0.00662653 0.0123056" mass="1.454" diaginertia="0.00163147 0.00160354 0.00118381"/>
                <!-- <site name="link5_iner" pos="-2.8e-05 -0.025911 -0.004363" rgba="0 1 0 0.5"/> -->
                <joint name="wrist2" pos="0 0 0" axis="0 0 1" range="-3.14 3.14" actuatorfrcrange="-10 10" />
                <geom mesh="link5_0" material="Material.001" class="visual"/>
                <geom mesh="link5_1" material="64,64,64_4" class="visual"/>
                <geom mesh="link5_2" material="204,204,204_2" class="visual"/>
                <geom mesh="link5_3" material="125,125,125_2" class="visual"/>
                <geom mesh="link5_4" material="244,244,244_2" class="visual"/>
                <geom class="collision" size="0.035 0.045" rgba="0 1 0 0.3" pos="0 -0.00 -0.05" euler="0 0 0"/>            
                <!-- <geom mesh="link5_0" class="collision"/>
                <geom mesh="link5_1" class="collision"/>
                <geom mesh="link5_2" class="collision"/>
                <geom mesh="link5_3" class="collision"/>
                <geom mesh="link5_4" class="collision"/> -->
                <body name="link6">
                  <inertial pos="-2e-06 -0.079964 -0.000494" quat="0.706709 -0.0427371 -0.0387873 0.705146" mass="0.243" diaginertia="0.000243707 0.000147897 0.000142261"/>
                  <!-- <site name="link6_iner" pos="-2e-06 -0.079964 -0.000494" rgba="0 1 0 0.5"/> -->
                  <joint name="wrist3" pos="0 0 0" axis="0 1 0" range="-3.14 3.14" actuatorfrcrange="-10 10" />
                  <geom mesh="link6_0" material="254,254,255" class="visual"/>
                  <geom mesh="link6_1" material="128,128,128_3" class="visual"/>
                  <geom class="collision" size="0.035 0.030" rgba="0 1 0 0.3" pos="0 -0.02 0" euler="1.57 0 0"/>
                  <!-- <geom mesh="link6_0" class="collision"/>
                  <geom mesh="link6_1" class="collision"/>                 -->
                  <site name="attachment_site" pos="0 -0.1 0" quat="1 1 0 0" />

                </body>
              </body>
            </body>
          </body>
        </body>
      </body>
    </body>
  </worldbody>

  <actuator>
    <general class="size3" name="base" joint="base" />
    <general class="size3" name="shoulder" joint="shoulder" />
    <general class="size3_limited" name="elbow" joint="elbow" />
    <general class="size1" name="wrist_1" joint="wrist1" />
    <general class="size1" name="wrist_2" joint="wrist2" />
    <general class="size1" name="wrist_3" joint="wrist3" />
  </actuator>

  <contact>
    <exclude body1="link0" body2="link1" />
    <!-- <exclude body1="link2" body2="link4" />    -->
  </contact>

</mujoco>

